Workbook

Sheet Instrucoes
A1: Coleta de dados — Estudo comparativo de ferramentas de IA generativa
A2: 15 problemas × 3 ferramentas × 2 execuções = 90 coletas · Beecrowd · Python 3
A4: FERRAMENTAS AVALIADAS
A5: Ferramenta 1 | B5: ChatGPT | C5: GPT-5.6 Luna | D5: ← confirme o modelo na interface a cada execução
A6: Ferramenta 2 | B6: Gemini | C6: Gemini 3.6 Flash
A7: Ferramenta 3 | B7: Claude | C7: Claude Sonnet 5
A9: O QUE ESTE ESTUDO MEDE
A10: • Corretude — veredito do juiz: aceito de primeira, rodadas até aceitar, resultado final
A11: • Autocorreção — o que acontece quando a ferramenta recebe o veredito de erro de volta
A12: • Qualidade do código — Pylint e Radon (preenchido por mim, não por você)
A13: • Eficiência — tempo de execução do programa, reportado pelo Beecrowd
A14: • Consistência — concordância entre a Execução 1 e a Execução 2
A17: COMO PREENCHER
A18: 1. Só as células amarelas. ID, nível e ferramenta já vêm por fórmula.
A19: 2. Execução 1: linhas 3 a 47. Execução 2: linhas 48 a 92 (em verde), em outra data.
A20: 3. Registre o veredito de CADA tentativa, não só da primeira — é o que mede autocorreção.
A21: 4. Não há cronometragem. Nenhum campo depende de você medir tempo.
A22: 5. Salve os códigos em ..\codigos como 1131_chatgpt_1.py e me avise ao terminar.
... A30: • Nunca corrija o código por conta própria. Nenhuma intervenção manual.

Sheet Problemas
A1: Problemas selecionados
A2: Escala de dificuldade do Beecrowd (1-10), agrupada como em Souza e Gheyi (2023).
A4: Nº | B4: ID | C4: Título | D4: Faixa | E4: Nível | F4: Categoria | G4: Link
A5: 1 | B5: 1131 | C5: Grenais | D5: Fácil | E5: 1 | F5: Iniciante | G5: https://judge.beecrowd.com/en/problems/view/1131
A6: 2 | B6: 1961 | C6: Jumping Frog | D6: Fácil | E6: 2 | F6: Iniciante | G6: https://judge.beecrowd.com/en/problems/view/1961
A7: 3 | B7: 2551 | C7: New Record | D7: Fácil | E7: 3 | F7: Iniciante | G7: https://judge.beecrowd.com/en/problems/view/2551
A8: 4 | B8: 1253 | C8: Caesar Cipher | D8: Fácil | E8: 3 | F8: Strings | G8: https://judge.beecrowd.com/en/problems/view/1253
A9: 5 | B9: 2437 | C9: Manhattan Distance | D9: Fácil | E9: 4 | F9: Ad-Hoc | G9: https://judge.beecrowd.com/en/problems/view/2437
A10: 6 | B10: 2867 | C10: Digits | D10: Médio | E10: 5 | F10: Iniciante | G10: https://judge.beecrowd.com/en/problems/view/2867
A11: 7 | B11: 2253 | C11: Passwords Validator | D11: Médio | E11: 5 | F11: Strings | G11: https://judge.beecrowd.com/en/problems/view/2253
A12: 8 | B12: 1032 | C12: Joseph's Cousin | D12: Médio | E12: 6 | F12: Ad-Hoc | G12: https://judge.beecrowd.com/en/problems/view/1032
A13: 9 | B13: 1033 | C13: How Many Calls? | D13: Médio | E13: 6 | F13: Paradigmas | G13: https://judge.beecrowd.com/en/problems/view/1033
A14: 10 | B14: 1243 | C14: How Easy | D14: Médio | E14: 7 | F14: Strings | G14: https://judge.beecrowd.com/en/problems/view/1243
A15: 11 | B15: 1084 | C15: Erasing and Winning | D15: Difícil | E15: 8 | F15: Paradigmas | G15: https://judge.beecrowd.com/en/problems/view/1084
A16: 12 | B16: 1034 | C16: Ice Statues Festival | D16: Difícil | E16: 8 | F16: Paradigmas | G16: https://judge.beecrowd.com/en/problems/view/1034
... A19: 15 | B19: 1141 | C19: Growing Strings | D19: Difícil | E19: 10 | F19: Strings | G19: https://judge.beecrowd.com/en/problems/view/1141

Sheet Coleta
A1: ID Problema | B1: Faixa | C1: Ferramenta | D1: Execução | E1: Data da coleta | F1: Modelo / versão exibida | G1: Aceito na 1ª tentativa | H1: Rodadas até Accepted (1-3) | I1: Resultado final | J1: Veredito 1ª tentativa | K1: Veredito 2ª tentativa | L1: Veredito 3ª tentativa | M1: Score Pylint (0-10) | N1: Complexidade ciclomática (total) | O1: Índice de manutenibilidade | P1: LOC | Q1: Densidade de comentários (%) | R1: Forma do código | S1: Tempo de execução (s) | T1: Observações
A2: 1131 | B2: Fácil | C2: ChatGPT | D2: 1 | E2: 12/09/2026 | F2: GPT-5.6 Luna | G2: Não | H2: 2 | I2: Accepted | J2: Wrong Answer | K2: Accepted | L2: - | M2: 9.12 | N2: 5 | O2: 64.3 | P2: 18 | Q2: 0 | R2: script linear | S2: 0.048 | T2: EXEMPLO — apague o conteúdo desta linha
A3: =IF(Problemas!$B$5="","",Problemas!$B$5) -> 1131 | B3: =IF(Problemas!$D$5="","",Problemas!$D$5) -> Fácil | C3: =Instrucoes!$B$5 -> ChatGPT | D3: 1 | E3: 09/09/2026 | F3: GPT-5.6 Luna | G3: Sim | H3: 1 | I3: Accepted | J3: Accepted | K3: - | L3: - | M3: 10 | N3: 7 | O3: 54.66 | P3: 25 | Q3: 0 | R3: script linear | S3: 0
A4: =IF(Problemas!$B$5="","",Problemas!$B$5) -> 1131 | B4: =IF(Problemas!$D$5="","",Problemas!$D$5) -> Fácil | C4: =Instrucoes!$B$6 -> Gemini | D4: 1 | E4: 09/09/2026 | F4: Gemini 3.6 Flash | G4: Sim | H4: 1 | I4: Accepted | J4: Accepted | K4: - | L4: - | M4: 8.42 | N4: 10 | O4: 47.27 | P4: 41 | Q4: 0 | R4: com funções | S4: 0
A5: =IF(Problemas!$B$5="","",Problemas!$B$5) -> 1131 | B5: =IF(Problemas!$D$5="","",Problemas!$D$5) -> Fácil | C5: =Instrucoes!$B$7 -> Claude | D5: 1 | E5: 09/09/2026 | F5: Claude Sonnet 5 | G5: Sim | H5: 1 | I5: Accepted | J5: Accepted | K5: - | L5: - | M5: 9.14 | N5: 8 | O5: 49.43 | P5: 34 | Q5: 0 | R5: com funções | S5: 0
A6: =IF(Problemas!$B$6="","",Problemas!$B$6) -> 1961 | B6: =IF(Problemas!$D$6="","",Problemas!$D$6) -> Fácil | C6: =Instrucoes!$B$5 -> ChatGPT | D6: 1 | E6: 09/09/2026 | F6: GPT-5.6 Luna | G6: Sim | H6: 1 | I6: Accepted | J6: Accepted | K6: - | L6: - | M6: 10 | N6: 4 | O6: 68.55 | P6: 8 | Q6: 0 | R6: script linear | S6: 0
A7: =IF(Problemas!$B$6="","",Problemas!$B$6) -> 1961 | B7: =IF(Problemas!$D$6="","",Problemas!$D$6) -> Fácil | C7: =Instrucoes!$B$6 -> Gemini | D7: 1 | E7: 09/09/2026 | F7: Gemini 3.6 Flash | G7: Sim | H7: 1 | I7: Accepted | J7: Accepted | K7: - | L7: - | M7: 8 | N7: 6 | O7: 59.6 | P7: 15 | Q7: 0 | R7: com funções | S7: 0
A8: =IF(Problemas!$B$6="","",Problemas!$B$6) -> 1961 | B8: =IF(Problemas!$D$6="","",Problemas!$D$6) -> Fácil | C8: =Instrucoes!$B$7 -> Claude | D8: 1 | E8: 09/09/2026 | F8: Claude Sonnet 5 | G8: Sim | H8: 1 | I8: Accepted | J8: Accepted | K8: - | L8: - | M8: 8.12 | N8: 5 | O8: 60.62 | P8: 14 | Q8: 0 | R8: com funções | S8: 0
A9: =IF(Problemas!$B$7="","",Problemas!$B$7) -> 2551 | B9: =IF(Problemas!$D$7="","",Problemas!$D$7) -> Fácil | C9: =Instrucoes!$B$5 -> ChatGPT | D9: 1 | E9: 09/09/2026 | F9: GPT-5.6 Luna | G9: Não | I9: Falha | J9: Presentation Error | K9: Presentation Error | L9: Presentation Error | M9: 9.5 | N9: 6 | O9: 68.48 | P9: 20 | Q9: 0.0476 | R9: com funções | T9: Presentation Error nas três tentativas admitidas pelo protocolo: 49939457 (1ª), 49939477 (2ª) e 49939484 (3ª). Esgotado o limite de três tentativas, a coleta é encerrada como Falha. Houve uma QUARTA submissão (49939491, 11h23), aceita, que NÃO é computada por exceder o limite de três tentativas declarado no método, seguindo Souza e Gheyi (2023). O erro de apresentação decorre da ausência de quebra de linha final: a solução usa sys.stdout.write sem '\n' ao término. Métricas de qualidade medidas sobre a primeira resposta, como nas demais coletas.
A10: =IF(Problemas!$B$7="","",Problemas!$B$7) -> 2551 | B10: =IF(Problemas!$D$7="","",Problemas!$D$7) -> Fácil | C10: =Instrucoes!$B$6 -> Gemini | D10: 1 | E10: 09/09/2026 | F10: Gemini 3.6 Flash | G10: Sim | H10: 1 | I10: Accepted | J10: Accepted | K10: - | L10: - | M10: 6.19 | N10: 6 | O10: 55.82 | P10: 21 | Q10: 0 | R10: com funções | S10: 0
A11: =IF(Problemas!$B$7="","",Problemas!$B$7) -> 2551 | B11: =IF(Problemas!$D$7="","",Problemas!$D$7) -> Fácil | C11: =Instrucoes!$B$7 -> Claude | D11: 1 | E11: 09/09/2026 | F11: Claude Sonnet 5 | G11: Sim | H11: 1 | I11: Accepted | J11: Accepted | K11: - | L11: - | M11: 8.57 | N11: 5 | O11: 56.36 | P11: 18 | Q11: 0 | R11: com funções | S11: 0
A12: =IF(Problemas!$B$8="","",Problemas!$B$8) -> 1253 | B12: =IF(Problemas!$D$8="","",Problemas!$D$8) -> Fácil | C12: =Instrucoes!$B$5 -> ChatGPT | D12: 1 | E12: 09/09/2026 | F12: GPT-5.6 Luna | G12: Sim | H12: 1 | I12: Accepted | J12: Accepted | K12: - | L12: - | M12: 6.67 | N12: 3 | O12: 71.29 | P12: 9 | Q12: 0 | R12: script linear | S12: 0.781
A13: =IF(Problemas!$B$8="","",Problemas!$B$8) -> 1253 | B13: =IF(Problemas!$D$8="","",Problemas!$D$8) -> Fácil | C13: =Instrucoes!$B$6 -> Gemini | D13: 1 | E13: 09/09/2026 | F13: Gemini 3.6 Flash | G13: Sim | H13: 1 | I13: Accepted | J13: Accepted | K13: - | L13: - | M13: 8.18 | N13: 7 | O13: 66.49 | P13: 23 | Q13: 0.0417 | R13: com funções | S13: 0.132
A14: =IF(Problemas!$B$8="","",Problemas!$B$8) -> 1253 | B14: =IF(Problemas!$D$8="","",Problemas!$D$8) -> Fácil | C14: =Instrucoes!$B$7 -> Claude | D14: 1 | E14: 09/09/2026 | F14: Claude Sonnet 5 | G14: Sim | H14: 1 | I14: Accepted | J14: Accepted | K14: - | L14: - | M14: 8.5 | N14: 4 | O14: 57.2 | P14: 17 | Q14: 0 | R14: com funções | S14: 0.093
A15: =IF(Problemas!$B$9="","",Problemas!$B$9) -> 2437 | B15: =IF(Problemas!$D$9="","",Problemas!$D$9) -> Fácil | C15: =Instrucoes!$B$5 -> ChatGPT | D15: 1 | E15: 09/09/2026 | F15: GPT-5.6 Luna | G15: Sim | H15: 1 | I15: Accepted | J15: Accepted | K15: - | L15: - | M15: 10 | N15: 1 | O15: 83.28 | P15: 2 | Q15: 0 | R15: script linear | S15: 0
A16: =IF(Problemas!$B$9="","",Problemas!$B$9) -> 2437 | B16: =IF(Problemas!$D$9="","",Problemas!$D$9) -> Fácil | C16: =Instrucoes!$B$6 -> Gemini | D16: 1 | E16: 09/09/2026 | F16: Gemini 3.6 Flash | G16: Sim | H16: 1 | I16: Accepted | J16: Accepted | K16: - | L16: - | M16: 6 | N16: 3 | O16: 65.78 | P16: 10 | Q16: 0 | R16: com funções | S16: 0
A17: =IF(Problemas!$B$9="","",Problemas!$B$9) -> 2437 | B17: =IF(Problemas!$D$9="","",Problemas!$D$9) -> Fácil | C17: =Instrucoes!$B$7 -> Claude | D17: 1 | E17: 09/09/2026 | F17: Claude Sonnet 5 | G17: Sim | H17: 1 | I17: Accepted | J17: Accepted | K17: - | L17: - | M17: 10 | N17: 1 | O17: 83.28 | P17: 2 | Q17: 0 | R17: script linear | S17: 0
A18: =IF(Problemas!$B$10="","",Problemas!$B$10) -> 2867 | B18: =IF(Problemas!$D$10="","",Problemas!$D$10) -> Médio | C18: =Instrucoes!$B$5 -> ChatGPT | D18: 1 | E18: 09/09/2026 | F18: GPT-5.6 Luna | G18: Sim | H18: 1 | I18: Accepted | J18: Accepted | K18: - | L18: - | M18: 10 | N18: 4 | O18: 59.95 | P18: 17 | Q18: 0 | R18: com funções | S18: 0
A19: =IF(Problemas!$B$10="","",Problemas!$B$10) -> 2867 | B19: =IF(Problemas!$D$10="","",Problemas!$D$10) -> Médio | C19: =Instrucoes!$B$6 -> Gemini | D19: 1 | E19: 09/09/2026 | F19: Gemini 3.6 Flash | G19: Sim | H19: 1 | I19: Accepted | J19: Accepted | K19: - | L19: - | M19: 7 | N19: 6 | O19: 55.66 | P19: 21 | Q19: 0 | R19: com funções | S19: 0
A20: =IF(Problemas!$B$10="","",Problemas!$B$10) -> 2867 | B20: =IF(Problemas!$D$10="","",Problemas!$D$10) -> Médio | C20: =Instrucoes!$B$7 -> Claude | D20: 1 | E20: 09/09/2026 | F20: Claude Sonnet 5 | G20: Sim | H20: 1 | I20: Accepted | J20: Accepted | K20: - | L20: - | M20: 8.24 | N20: 3 | O20: 61.01 | P20: 14 | Q20: 0 | R20: com funções | S20: 0.015 | T20: A interface do Claude exibiu atividade própria antes de responder (indicador "Pensou por Ns" e, neste problema, "Executou um comando" — a ferramenta executou código antes de responder), recurso que não apareceu nas outras duas ferramentas nesta coleta. Registrado como diferença de capacidade entre as ferramentas, não como desvio de protocolo.
A21: =IF(Problemas!$B$11="","",Problemas!$B$11) -> 2253 | B21: =IF(Problemas!$D$11="","",Problemas!$D$11) -> Médio | C21: =Instrucoes!$B$5 -> ChatGPT | D21: 1 | E21: 09/09/2026 | F21: GPT-5.6 Luna | G21: Sim | H21: 1 | I21: Accepted | J21: Accepted | K21: - | L21: - | M21: 10 | N21: 11 | O21: 68.71 | P21: 12 | Q21: 0 | R21: script linear | S21: 0.032
A22: =IF(Problemas!$B$11="","",Problemas!$B$11) -> 2253 | B22: =IF(Problemas!$D$11="","",Problemas!$D$11) -> Médio | C22: =Instrucoes!$B$6 -> Gemini | D22: 1 | E22: 09/09/2026 | F22: Gemini 3.6 Flash | G22: Sim | H22: 1 | I22: Accepted | J22: Accepted | K22: - | L22: - | M22: 8 | N22: 12 | O22: 70.49 | P22: 27 | Q22: 0.069 | R22: com funções | S22: 0
A23: =IF(Problemas!$B$11="","",Problemas!$B$11) -> 2253 | B23: =IF(Problemas!$D$11="","",Problemas!$D$11) -> Médio | C23: =Instrucoes!$B$7 -> Claude | D23: 1 | E23: 09/09/2026 | F23: Claude Sonnet 5 | G23: Sim | H23: 1 | I23: Accepted | J23: Accepted | K23: - | L23: - | M23: 10 | N23: 12 | O23: 52.33 | P23: 27 | Q23: 0 | R23: com funções | S23: 0.001
A24: =IF(Problemas!$B$12="","",Problemas!$B$12) -> 1032 | B24: =IF(Problemas!$D$12="","",Problemas!$D$12) -> Médio | C24: =Instrucoes!$B$5 -> ChatGPT | D24: 1 | E24: 09/09/2026 | F24: GPT-5.6 Luna | G24: Não | H24: 2 | I24: Accepted | J24: Wrong Answer | K24: Accepted | L24: - | M24: 9.52 | N24: 21 | O24: 37.73 | P24: 63 | Q24: 0 | R24: com funções | S24: 0.002 | T24: Aceito na 2ª tentativa (autocorreção). 1ª: submissão 49939682, Wrong answer (75%), árvore de Fenwick, 84 linhas. 2ª: submissão 49939684, Accepted, 0,002 s, simulação direta com lista, 51 linhas — a ferramenta trocou de estratégia em vez de corrigir a anterior. Código da 2ª tentativa: codigos/correcoes/1032_chatgpt_1_tentativa2.py. DESVIO DE PROTOCOLO: o prompt de correção foi digitado como "O veredito foi Wrong answer (75%) . corrija", e não na forma padronizada "O código retornou [VEREDITO]. Corrija." O conteúdo informado é o mesmo — veredito realimentado e pedido de correção —, mas a redação difere.
A25: =IF(Problemas!$B$12="","",Problemas!$B$12) -> 1032 | B25: =IF(Problemas!$D$12="","",Problemas!$D$12) -> Médio | C25: =Instrucoes!$B$6 -> Gemini | D25: 1 | E25: 09/09/2026 | F25: Gemini 3.6 Flash | G25: Sim | H25: 1 | I25: Accepted | J25: Accepted | K25: - | L25: - | M25: 8.28 | N25: 9 | O25: 52.25 | P25: 29 | Q25: 0 | R25: com funções | S25: 0
A26: =IF(Problemas!$B$12="","",Problemas!$B$12) -> 1032 | B26: =IF(Problemas!$D$12="","",Problemas!$D$12) -> Médio | C26: =Instrucoes!$B$7 -> Claude | D26: 1 | E26: 09/09/2026 | F26: Claude Sonnet 5 | G26: Sim | H26: 1 | I26: Accepted | J26: Accepted | K26: - | L26: - | M26: 9.79 | N26: 17 | O26: 51.52 | P26: 48 | Q26: 0.0204 | R26: com funções | S26: 0.012 | T26: A interface do Claude exibiu atividade própria antes de responder ("Pensou por 4s"), recurso que não apareceu no ChatGPT nem no Gemini nesta coleta. Registrado como diferença de capacidade entre as ferramentas, não como desvio de protocolo.
A27: =IF(Problemas!$B$13="","",Problemas!$B$13) -> 1033 | B27: =IF(Problemas!$D$13="","",Problemas!$D$13) -> Médio | C27: =Instrucoes!$B$5 -> ChatGPT | D27: 1 | E27: 09/09/2026 | F27: GPT-5.6 Luna | G27: Sim | H27: 1 | I27: Accepted | J27: Accepted | K27: - | L27: - | M27: 10 | N27: 9 | O27: 67.89 | P27: 41 | Q27: 0.1277 | R27: com funções | S27: 0.04
A28: =IF(Problemas!$B$13="","",Problemas!$B$13) -> 1033 | B28: =IF(Problemas!$D$13="","",Problemas!$D$13) -> Médio | C28: =Instrucoes!$B$6 -> Gemini | D28: 1 | E28: 09/09/2026 | F28: Gemini 3.6 Flash | G28: Sim | H28: 1 | I28: Accepted | J28: Accepted | K28: - | L28: - | M28: 7.43 | N28: 10 | O28: 59.59 | P28: 54 | Q28: 0.0847 | R28: com funções | S28: 0.099
A29: =IF(Problemas!$B$13="","",Problemas!$B$13) -> 1033 | B29: =IF(Problemas!$D$13="","",Problemas!$D$13) -> Médio | C29: =Instrucoes!$B$7 -> Claude | D29: 1 | E29: 09/09/2026 | F29: Claude Sonnet 5 | G29: Sim | H29: 1 | I29: Accepted | J29: Accepted | K29: - | L29: - | M29: 9.26 | N29: 6 | O29: 49.14 | P29: 26 | Q29: 0 | R29: com funções | S29: 0.005 | T29: A interface do Claude exibiu atividade própria antes de responder ("Pensou por 15s"), recurso que não apareceu no ChatGPT nem no Gemini nesta coleta. Registrado como diferença de capacidade entre as ferramentas, não como desvio de protocolo.
A30: =IF(Problemas!$B$14="","",Problemas!$B$14) -> 1243 | B30: =IF(Problemas!$D$14="","",Problemas!$D$14) -> Médio | C30: =Instrucoes!$B$5 -> ChatGPT | D30: 1 | E30: 09/09/2026 | F30: GPT-5.6 Luna | G30: Sim | H30: 1 | I30: Accepted | J30: Accepted | K30: - | L30: - | M30: 10 | N30: 11 | O30: 57.39 | P30: 17 | Q30: 0 | R30: script linear | S30: 0.09
A31: =IF(Problemas!$B$14="","",Problemas!$B$14) -> 1243 | B31: =IF(Problemas!$D$14="","",Problemas!$D$14) -> Médio | C31: =Instrucoes!$B$6 -> Gemini | D31: 1 | E31: 09/09/2026 | F31: Gemini 3.6 Flash | G31: Sim | H31: 1 | I31: Accepted | J31: Accepted | K31: - | L31: - | M31: 9.62 | N31: 10 | O31: 66.83 | P31: 29 | Q31: 0.0645 | R31: com funções | S31: 0.029
A32: =IF(Problemas!$B$14="","",Problemas!$B$14) -> 1243 | B32: =IF(Problemas!$D$14="","",Problemas!$D$14) -> Médio | C32: =Instrucoes!$B$7 -> Claude | D32: 1 | E32: 09/09/2026 | F32: Claude Sonnet 5 | G32: Sim | H32: 1 | I32: Accepted | J32: Accepted | K32: - | L32: - | M32: 9.26 | N32: 11 | O32: 51.73 | P32: 29 | Q32: 0 | R32: com funções | S32: 0.082 | T32: A interface do Claude exibiu atividade própria antes de responder ("Pensou por 7s"), recurso que não apareceu no ChatGPT nem no Gemini nesta coleta. Registrado como diferença de capacidade entre as ferramentas, não como desvio de protocolo.
A33: =IF(Problemas!$B$15="","",Problemas!$B$15) -> 1084 | B33: =IF(Problemas!$D$15="","",Problemas!$D$15) -> Difícil | C33: =Instrucoes!$B$5 -> ChatGPT | D33: 1 | E33: 09/09/2026 | F33: GPT-5.6 Luna | G33: Sim | H33: 1 | I33: Accepted | J33: Accepted | K33: - | L33: - | M33: 9.57 | N33: 11 | O33: 53.14 | P33: 23 | Q33: 0 | R33: com funções | S33: 0.095
A34: =IF(Problemas!$B$15="","",Problemas!$B$15) -> 1084 | B34: =IF(Problemas!$D$15="","",Problemas!$D$15) -> Difícil | C34: =Instrucoes!$B$6 -> Gemini | D34: 1 | E34: 09/09/2026 | F34: Gemini 3.6 Flash | G34: Sim | H34: 1 | I34: Accepted | J34: Accepted | K34: - | L34: - | M34: 6.3 | N34: 10 | O34: 50.87 | P34: 27 | Q34: 0 | R34: com funções | S34: 0.097
A35: =IF(Problemas!$B$15="","",Problemas!$B$15) -> 1084 | B35: =IF(Problemas!$D$15="","",Problemas!$D$15) -> Difícil | C35: =Instrucoes!$B$7 -> Claude | D35: 1 | E35: 09/09/2026 | F35: Claude Sonnet 5 | G35: Sim | H35: 1 | I35: Accepted | J35: Accepted | K35: - | L35: - | M35: 9.2 | N35: 8 | O35: 52.37 | P35: 22 | Q35: 0 | R35: com funções | S35: 0.131 | T35: Submissão 49940062 (1ª e válida). A submissão 49940440, às 13h22, é o MESMO código reenviado — byte a byte idêntico, 609 B — e não constitui nova tentativa.
A36: =IF(Problemas!$B$16="","",Problemas!$B$16) -> 1034 | B36: =IF(Problemas!$D$16="","",Problemas!$D$16) -> Difícil | C36: =Instrucoes!$B$5 -> ChatGPT | D36: 1 | E36: 09/09/2026 | F36: GPT-5.6 Luna | G36: Não | I36: Falha | J36: Time Limit Exceeded | K36: Time Limit Exceeded | L36: Presentation Error | M36: 9.63 | N36: 7 | O36: 67.3 | P36: 27 | Q36: 0.069 | R36: com funções | T36: Três tentativas esgotadas sem aceitação: 49940064 (TLE), 49940075 (TLE) e 49940088 (Presentation error). Códigos: codigos/correcoes/1034_chatgpt_1_tentativa2.py e _tentativa3.py.
A37: =IF(Problemas!$B$16="","",Problemas!$B$16) -> 1034 | B37: =IF(Problemas!$D$16="","",Problemas!$D$16) -> Difícil | C37: =Instrucoes!$B$6 -> Gemini | D37: 1 | E37: 09/09/2026 | F37: Gemini 3.6 Flash | G37: Não | I37: Falha | J37: Time Limit Exceeded | K37: Time Limit Exceeded | L37: Time Limit Exceeded | M37: 5.83 | N37: 8 | O37: 52.59 | P37: 24 | Q37: 0 | R37: com funções | T37: Três tentativas esgotadas, todas Time limit exceeded: 49940334, 49940355 e 49940363. Códigos: codigos/correcoes/1034_gemini_1_tentativa2.py e _tentativa3.py.
A38: =IF(Problemas!$B$16="","",Problemas!$B$16) -> 1034 | B38: =IF(Problemas!$D$16="","",Problemas!$D$16) -> Difícil | C38: =Instrucoes!$B$7 -> Claude | D38: 1 | E38: 09/09/2026 | F38: Claude Sonnet 5 | G38: Não | I38: Falha | J38: Time Limit Exceeded | K38: Runtime Error | L38: Time Limit Exceeded | M38: 7.59 | N38: 10 | O38: 50.44 | P38: 26 | Q38: 0 | R38: com funções | T38: Três tentativas esgotadas: 49940429 (TLE), 49940516 (Runtime error) e 49940553 (TLE). Códigos: codigos/correcoes/1034_claude_1_tentativa2.py (confere com 49940516) e _tentativa3.py (confere com 49940553). Houve duas submissões adicionais fora do protocolo: 49940460, byte a byte idêntica a 49940429 (mesmo código reenviado), e 49940478 (706 B), que não corresponde a nenhuma versão salva do Claude — colagem equivocada. Nenhuma das cinco foi aceita, de modo que o desfecho Falha não depende da leitura adotada.
A39: =IF(Problemas!$B$17="","",Problemas!$B$17) -> 1027 | B39: =IF(Problemas!$D$17="","",Problemas!$D$17) -> Difícil | C39: =Instrucoes!$B$5 -> ChatGPT | D39: 1 | E39: 09/09/2026 | F39: GPT-5.6 Luna | G39: Não | I39: Falha | J39: Wrong Answer | K39: Presentation Error | L39: Wrong Answer | M39: 10 | N39: 10 | O39: 47.7 | P39: 41 | Q39: 0 | R39: com funções | T39: Três tentativas esgotadas sem aceitação: 49940570 (Wrong answer 5%), 49940610 (Presentation error 100%) e 49943694 (Wrong answer 5%). A 3ª tentativa retornou ao mesmo veredito da 1ª. Códigos: codigos/correcoes/1027_chatgpt_1_tentativa2.txt e _tentativa3.py.
A40: =IF(Problemas!$B$17="","",Problemas!$B$17) -> 1027 | B40: =IF(Problemas!$D$17="","",Problemas!$D$17) -> Difícil | C40: =Instrucoes!$B$6 -> Gemini | D40: 1 | E40: 09/09/2026 | F40: Gemini 3.6 Flash | G40: Não | H40: 2 | I40: Accepted | J40: Wrong Answer | K40: Accepted | L40: - | M40: 7.44 | N40: 29 | O40: 48.48 | P40: 88 | Q40: 0.0638 | R40: com funções | S40: 0.195 | T40: Autocorreção bem-sucedida: 49940635 (Wrong answer 5%) e 49940645 (Accepted). Código da 2ª tentativa: codigos/correcoes/1027_gemini_1_ tentativa2.py.
...

Sheet Consolidacao
A1: Consolidação dos resultados
A2: Calculado a partir da aba Coleta, somando as duas execuções.
A4: Métrica | B4: =Instrucoes!$B$5 -> ChatGPT | C4: =Instrucoes!$B$6 -> Gemini | D4: =Instrucoes!$B$7 -> Claude
A5: Coletas registradas | B5: =COUNTIFS(Coleta!$C$3:$C$92,B$4,Coleta!$I$3:$I$92,"<>") -> 30 | C5: =COUNTIFS(Coleta!$C$3:$C$92,C$4,Coleta!$I$3:$I$92,"<>") -> 30 | D5: =COUNTIFS(Coleta!$C$3:$C$92,D$4,Coleta!$I$3:$I$92,"<>") -> 30
A6: Aceito na 1ª tentativa (%) | B6: =IFERROR(COUNTIFS(Coleta!$C$3:$C$92,B$4,Coleta!$G$3:$G$92,"Sim")/COUNTIFS(Coleta!$C$3:$C$92,B$4,Coleta!$G$3:$G$92,"<>"),"") -> 0.56666667 | C6: =IFERROR(COUNTIFS(Coleta!$C$3:$C$92,C$4,Coleta!$G$3:$G$92,"Sim")/COUNTIFS(Coleta!$C$3:$C$92,C$4,Coleta!$G$3:$G$92,"<>"),"") -> 0.7 | D6: =IFERROR(COUNTIFS(Coleta!$C$3:$C$92,D$4,Coleta!$G$3:$G$92,"Sim")/COUNTIFS(Coleta!$C$3:$C$92,D$4,Coleta!$G$3:$G$92,"<>"),"") -> 0.8
A7: Taxa de sucesso final (%) | B7: =IFERROR(COUNTIFS(Coleta!$C$3:$C$92,B$4,Coleta!$I$3:$I$92,"Accepted")/COUNTIFS(Coleta!$C$3:$C$92,B$4,Coleta!$I$3:$I$92,"<>"),"") -> 0.7 | C7: =IFERROR(COUNTIFS(Coleta!$C$3:$C$92,C$4,Coleta!$I$3:$I$92,"Accepted")/COUNTIFS(Coleta!$C$3:$C$92,C$4,Coleta!$I$3:$I$92,"<>"),"") -> 0.8 | D7: =IFERROR(COUNTIFS(Coleta!$C$3:$C$92,D$4,Coleta!$I$3:$I$92,"Accepted")/COUNTIFS(Coleta!$C$3:$C$92,D$4,Coleta!$I$3:$I$92,"<>"),"") -> 0.8
A8: Taxa de autocorreção (%) | B8: =IFERROR(COUNTIFS(Coleta!$C$3:$C$92,B$4,Coleta!$G$3:$G$92,"Não",Coleta!$I$3:$I$92,"Accepted",Coleta!$J$3:$J$92,"<>Não extraível")/COUNTIFS(Coleta!$C$3:$C$92,B$4,Coleta!$G$3:$G$92,"Não",Coleta!$J$3:$J$92,"<>Não extraível"),"") -> 0.30769231 | C8: =IFERROR(COUNTIFS(Coleta!$C$3:$C$92,C$4,Coleta!$G$3:$G$92,"Não",Coleta!$I$3:$I$92,"Accepted",Coleta!$J$3:$J$92,"<>Não extraível")/COUNTIFS(Coleta!$C$3:$C$92,C$4,Coleta!$G$3:$G$92,"Não",Coleta!$J$3:$J$92,"<>Não extraível"),"") -> 0.33333333 | D8: =IFERROR(COUNTIFS(Coleta!$C$3:$C$92,D$4,Coleta!$G$3:$G$92,"Não",Coleta!$I$3:$I$92,"Accepted",Coleta!$J$3:$J$92,"<>Não extraível")/COUNTIFS(Coleta!$C$3:$C$92,D$4,Coleta!$G$3:$G$92,"Não",Coleta!$J$3:$J$92,"<>Não extraível"),"") -> 0
A9: Consistência entre execuções (%) | B9: =IFERROR(AVERAGE(J41:J85),"") -> 0.8 | C9: =IFERROR(AVERAGE(K41:K85),"") -> 0.93333333 | D9: =IFERROR(AVERAGE(L41:L85),"") -> 1
A10: Rodadas médias até aceitação | B10: =IFERROR(AVERAGEIFS(Coleta!$H$3:$H$92,Coleta!$C$3:$C$92,B$4),"") -> 1.2380952 | C10: =IFERROR(AVERAGEIFS(Coleta!$H$3:$H$92,Coleta!$C$3:$C$92,C$4),"") -> 1.125 | D10: =IFERROR(AVERAGEIFS(Coleta!$H$3:$H$92,Coleta!$C$3:$C$92,D$4),"") -> 1
A11: Score Pylint médio (0-10) | B11: =IFERROR(AVERAGEIFS(Coleta!$M$3:$M$92,Coleta!$C$3:$C$92,B$4),"") -> 9.366 | C11: =IFERROR(AVERAGEIFS(Coleta!$M$3:$M$92,Coleta!$C$3:$C$92,C$4),"") -> 7.2593333 | D11: =IFERROR(AVERAGEIFS(Coleta!$M$3:$M$92,Coleta!$C$3:$C$92,D$4),"") -> 8.8156667
A12: Desvio-padrão do Score Pylint | B12: =IFERROR(STDEV(B41:B130),"") -> 1.09838 | C12: =IFERROR(STDEV(C41:C130),"") -> 1.1575746 | D12: =IFERROR(STDEV(D41:D130),"") -> 0.74227369
A13: Complexidade ciclomática média | B13: =IFERROR(AVERAGEIFS(Coleta!$N$3:$N$92,Coleta!$C$3:$C$92,B$4),"") -> 11.133333 | C13: =IFERROR(AVERAGEIFS(Coleta!$N$3:$N$92,Coleta!$C$3:$C$92,C$4),"") -> 10.8 | D13: =IFERROR(AVERAGEIFS(Coleta!$N$3:$N$92,Coleta!$C$3:$C$92,D$4),"") -> 9.4666667
A14: Desvio-padrão da complexidade | B14: =IFERROR(STDEV(F41:F130),"") -> 9.3614519 | C14: =IFERROR(STDEV(G41:G130),"") -> 6.1834038 | D14: =IFERROR(STDEV(H41:H130),"") -> 6.1685148
A15: Índice de manutenibilidade médio | B15: =IFERROR(AVERAGEIFS(Coleta!$O$3:$O$92,Coleta!$C$3:$C$92,B$4),"") -> 59.143667 | C15: =IFERROR(AVERAGEIFS(Coleta!$O$3:$O$92,Coleta!$C$3:$C$92,C$4),"") -> 57.655667 | D15: =IFERROR(AVERAGEIFS(Coleta!$O$3:$O$92,Coleta!$C$3:$C$92,D$4),"") -> 54.029333
A16: LOC médio | B16: =IFERROR(AVERAGEIFS(Coleta!$P$3:$P$92,Coleta!$C$3:$C$92,B$4),"") -> 33.933333 | C16: =IFERROR(AVERAGEIFS(Coleta!$P$3:$P$92,Coleta!$C$3:$C$92,C$4),"") -> 32.166667 | D16: =IFERROR(AVERAGEIFS(Coleta!$P$3:$P$92,Coleta!$C$3:$C$92,D$4),"") -> 33.6
A17: Densidade média de comentários (%) | B17: =IFERROR(AVERAGEIFS(Coleta!$Q$3:$Q$92,Coleta!$C$3:$C$92,B$4),"") -> 0.02157 | C17: =IFERROR(AVERAGEIFS(Coleta!$Q$3:$Q$92,Coleta!$C$3:$C$92,C$4),"") -> 0.03543 | D17: =IFERROR(AVERAGEIFS(Coleta!$Q$3:$Q$92,Coleta!$C$3:$C$92,D$4),"") -> 0.0054466667
A18: Soluções em script linear (%) | B18: =IFERROR(COUNTIFS(Coleta!$C$3:$C$92,B$4,Coleta!$R$3:$R$92,"script linear")/COUNTIFS(Coleta!$C$3:$C$92,B$4,Coleta!$R$3:$R$92,"<>"),"") -> 0.46666667 | C18: =IFERROR(COUNTIFS(Coleta!$C$3:$C$92,C$4,Coleta!$R$3:$R$92,"script linear")/COUNTIFS(Coleta!$C$3:$C$92,C$4,Coleta!$R$3:$R$92,"<>"),"") -> 0 | D18: =IFERROR(COUNTIFS(Coleta!$C$3:$C$92,D$4,Coleta!$R$3:$R$92,"script linear")/COUNTIFS(Coleta!$C$3:$C$92,D$4,Coleta!$R$3:$R$92,"<>"),"") -> 0.066666667
A19: Tempo médio de execução (s) | B19: =IFERROR(AVERAGEIFS(Coleta!$S$3:$S$92,Coleta!$C$3:$C$92,B$4),"") -> 0.12333333 | C19: =IFERROR(AVERAGEIFS(Coleta!$S$3:$S$92,Coleta!$C$3:$C$92,C$4),"") -> 0.045458333 | D19: =IFERROR(AVERAGEIFS(Coleta!$S$3:$S$92,Coleta!$C$3:$C$92,D$4),"") -> 0.115625
A20: Coletas não extraíveis (falha de entrega) | B20: =COUNTIFS(Coleta!$C$3:$C$92,B$4,Coleta!$J$3:$J$92,"Não extraível") -> 0 | C20: =COUNTIFS(Coleta!$C$3:$C$92,C$4,Coleta!$J$3:$J$92,"Não extraível") -> 0 | D20: =COUNTIFS(Coleta!$C$3:$C$92,D$4,Coleta!$J$3:$J$92,"Não extraível") -> 0
A22: Taxa de sucesso final por faixa de dificuldade
A23: Faixa | B23: =B$4 -> ChatGPT | C23: =C$4 -> Gemini | D23: =D$4 -> Claude
A24: Fácil | B24: =IFERROR(COUNTIFS(Coleta!$C$3:$C$92,B$4,Coleta!$B$3:$B$92,$A24,Coleta!$I$3:$I$92,"Accepted")/COUNTIFS(Coleta!$C$3:$C$92,B$4,Coleta!$B$3:$B$92,$A24,Coleta!$I$3:$I$92,"<>"),"") -> 0.8 | C24: =IFERROR(COUNTIFS(Coleta!$C$3:$C$92,C$4,Coleta!$B$3:$B$92,$A24,Coleta!$I$3:$I$92,"Accepted")/COUNTIFS(Coleta!$C$3:$C$92,C$4,Coleta!$B$3:$B$92,$A24,Coleta!$I$3:$I$92,"<>"),"") -> 1 | D24: =IFERROR(COUNTIFS(Coleta!$C$3:$C$92,D$4,Coleta!$B$3:$B$92,$A24,Coleta!$I$3:$I$92,"Accepted")/COUNTIFS(Coleta!$C$3:$C$92,D$4,Coleta!$B$3:$B$92,$A24,Coleta!$I$3:$I$92,"<>"),"") -> 1
A25: Médio | B25: =IFERROR(COUNTIFS(Coleta!$C$3:$C$92,B$4,Coleta!$B$3:$B$92,$A25,Coleta!$I$3:$I$92,"Accepted")/COUNTIFS(Coleta!$C$3:$C$92,B$4,Coleta!$B$3:$B$92,$A25,Coleta!$I$3:$I$92,"<>"),"") -> 1 | C25: =IFERROR(COUNTIFS(Coleta!$C$3:$C$92,C$4,Coleta!$B$3:$B$92,$A25,Coleta!$I$3:$I$92,"Accepted")/COUNTIFS(Coleta!$C$3:$C$92,C$4,Coleta!$B$3:$B$92,$A25,Coleta!$I$3:$I$92,"<>"),"") -> 1 | D25: =IFERROR(COUNTIFS(Coleta!$C$3:$C$92,D$4,Coleta!$B$3:$B$92,$A25,Coleta!$I$3:$I$92,"Accepted")/COUNTIFS(Coleta!$C$3:$C$92,D$4,Coleta!$B$3:$B$92,$A25,Coleta!$I$3:$I$92,"<>"),"") -> 1
A26: Difícil | B26: =IFERROR(COUNTIFS(Coleta!$C$3:$C$92,B$4,Coleta!$B$3:$B$92,$A26,Coleta!$I$3:$I$92,"Accepted")/COUNTIFS(Coleta!$C$3:$C$92,B$4,Coleta!$B$3:$B$92,$A26,Coleta!$I$3:$I$92,"<>"),"") -> 0.3 | C26: =IFERROR(COUNTIFS(Coleta!$C$3:$C$92,C$4,Coleta!$B$3:$B$92,$A26,Coleta!$I$3:$I$92,"Accepted")/COUNTIFS(Coleta!$C$3:$C$92,C$4,Coleta!$B$3:$B$92,$A26,Coleta!$I$3:$I$92,"<>"),"") -> 0.4 | D26: =IFERROR(COUNTIFS(Coleta!$C$3:$C$92,D$4,Coleta!$B$3:$B$92,$A26,Coleta!$I$3:$I$92,"Accepted")/COUNTIFS(Coleta!$C$3:$C$92,D$4,Coleta!$B$3:$B$92,$A26,Coleta!$I$3:$I$92,"<>"),"") -> 0.4
A28: Tipologia dos vereditos na 1ª tentativa
A29: Veredito | B29: =B$4 -> ChatGPT | C29: =C$4 -> Gemini | D29: =D$4 -> Claude
A30: Accepted | B30: =COUNTIFS(Coleta!$C$3:$C$92,B$4,Coleta!$J$3:$J$92,$A30) -> 17 | C30: =COUNTIFS(Coleta!$C$3:$C$92,C$4,Coleta!$J$3:$J$92,$A30) -> 21 | D30: =COUNTIFS(Coleta!$C$3:$C$92,D$4,Coleta!$J$3:$J$92,$A30) -> 24
A31: Wrong Answer | B31: =COUNTIFS(Coleta!$C$3:$C$92,B$4,Coleta!$J$3:$J$92,$A31) -> 6 | C31: =COUNTIFS(Coleta!$C$3:$C$92,C$4,Coleta!$J$3:$J$92,$A31) -> 2 | D31: =COUNTIFS(Coleta!$C$3:$C$92,D$4,Coleta!$J$3:$J$92,$A31) -> 0
A32: Time Limit Exceeded | B32: =COUNTIFS(Coleta!$C$3:$C$92,B$4,Coleta!$J$3:$J$92,$A32) -> 3 | C32: =COUNTIFS(Coleta!$C$3:$C$92,C$4,Coleta!$J$3:$J$92,$A32) -> 7 | D32: =COUNTIFS(Coleta!$C$3:$C$92,D$4,Coleta!$J$3:$J$92,$A32) -> 3
A33: Runtime Error | B33: =COUNTIFS(Coleta!$C$3:$C$92,B$4,Coleta!$J$3:$J$92,$A33) -> 1 | C33: =COUNTIFS(Coleta!$C$3:$C$92,C$4,Coleta!$J$3:$J$92,$A33) -> 0 | D33: =COUNTIFS(Coleta!$C$3:$C$92,D$4,Coleta!$J$3:$J$92,$A33) -> 2
A34: Compilation Error | B34: =COUNTIFS(Coleta!$C$3:$C$92,B$4,Coleta!$J$3:$J$92,$A34) -> 0 | C34: =COUNTIFS(Coleta!$C$3:$C$92,C$4,Coleta!$J$3:$J$92,$A34) -> 0 | D34: =COUNTIFS(Coleta!$C$3:$C$92,D$4,Coleta!$J$3:$J$92,$A34) -> 0
A35: Presentation Error | B35: =COUNTIFS(Coleta!$C$3:$C$92,B$4,Coleta!$J$3:$J$92,$A35) -> 3 | C35: =COUNTIFS(Coleta!$C$3:$C$92,C$4,Coleta!$J$3:$J$92,$A35) -> 0 | D35: =COUNTIFS(Coleta!$C$3:$C$92,D$4,Coleta!$J$3:$J$92,$A35) -> 0
A36: Memory Limit Exceeded | B36: =COUNTIFS(Coleta!$C$3:$C$92,B$4,Coleta!$J$3:$J$92,$A36) -> 0 | C36: =COUNTIFS(Coleta!$C$3:$C$92,C$4,Coleta!$J$3:$J$92,$A36) -> 0 | D36: =COUNTIFS(Coleta!$C$3:$C$92,D$4,Coleta!$J$3:$J$92,$A36) -> 1
A37: Não extraível | B37: =COUNTIFS(Coleta!$C$3:$C$92,B$4,Coleta!$J$3:$J$92,$A37) -> 0 | C37: =COUNTIFS(Coleta!$C$3:$C$92,C$4,Coleta!$J$3:$J$92,$A37) -> 0 | D37: =COUNTIFS(Coleta!$C$3:$C$92,D$4,Coleta!$J$3:$J$92,$A37) -> 0
A39: ÁREA AUXILIAR — não editar
A40: Pylint (B:D) · Complexidade (F:H) · Consistência (J:L)
B41: =IF(Coleta!$C3=B$4,IF(Coleta!$M3="","",Coleta!$M3),"") -> 10 | C41: =IF(Coleta!$C3=C$4,IF(Coleta!$M3="","",Coleta!$M3),"") | D41: =IF(Coleta!$C3=D$4,IF(Coleta!$M3="","",Coleta!$M3),"") | F41: =IF(Coleta!$C3=B$4,IF(Coleta!$N3="","",Coleta!$N3),"") -> 7 | G41: =IF(Coleta!$C3=C$4,IF(Coleta!$N3="","",Coleta!$N3),"") | H41: =IF(Coleta!$C3=D$4,IF(Coleta!$N3="","",Coleta!$N3),"") | J41: =IF(Coleta!$C3<>B$4,"",IF(OR(Coleta!$G3="",Coleta!$G48=""),"",IF(Coleta!$G3=Coleta!$G48,1,0))) -> 1 | K41: =IF(Coleta!$C3<>C$4,"",IF(OR(Coleta!$G3="",Coleta!$G48=""),"",IF(Coleta!$G3=Coleta!$G48,1,0))) | L41: =IF(Coleta!$C3<>D$4,"",IF(OR(Coleta!$G3="",Coleta!$G48=""),"",IF(Coleta!$G3=Coleta!$G48,1,0)))
B42: =IF(Coleta!$C4=B$4,IF(Coleta!$M4="","",Coleta!$M4),"") | C42: =IF(Coleta!$C4=C$4,IF(Coleta!$M4="","",Coleta!$M4),"") -> 8.42 | D42: =IF(Coleta!$C4=D$4,IF(Coleta!$M4="","",Coleta!$M4),"") | F42: =IF(Coleta!$C4=B$4,IF(Coleta!$N4="","",Coleta!$N4),"") | G42: =IF(Coleta!$C4=C$4,IF(Coleta!$N4="","",Coleta!$N4),"") -> 10 | H42: =IF(Coleta!$C4=D$4,IF(Coleta!$N4="","",Coleta!$N4),"") | J42: =IF(Coleta!$C4<>B$4,"",IF(OR(Coleta!$G4="",Coleta!$G49=""),"",IF(Coleta!$G4=Coleta!$G49,1,0))) | K42: =IF(Coleta!$C4<>C$4,"",IF(OR(Coleta!$G4="",Coleta!$G49=""),"",IF(Coleta!$G4=Coleta!$G49,1,0))) -> 1 | L42: =IF(Coleta!$C4<>D$4,"",IF(OR(Coleta!$G4="",Coleta!$G49=""),"",IF(Coleta!$G4=Coleta!$G49,1,0)))
B43: =IF(Coleta!$C5=B$4,IF(Coleta!$M5="","",Coleta!$M5),"") | C43: =IF(Coleta!$C5=C$4,IF(Coleta!$M5="","",Coleta!$M5),"") | D43: =IF(Coleta!$C5=D$4,IF(Coleta!$M5="","",Coleta!$M5),"") -> 9.14 | F43: =IF(Coleta!$C5=B$4,IF(Coleta!$N5="","",Coleta!$N5),"") | G43: =IF(Coleta!$C5=C$4,IF(Coleta!$N5="","",Coleta!$N5),"") | H43: =IF(Coleta!$C5=D$4,IF(Coleta!$N5="","",Coleta!$N5),"") -> 8 | J43: =IF(Coleta!$C5<>B$4,"",IF(OR(Coleta!$G5="",Coleta!$G50=""),"",IF(Coleta!$G5=Coleta!$G50,1,0))) | K43: =IF(Coleta!$C5<>C$4,"",IF(OR(Coleta!$G5="",Coleta!$G50=""),"",IF(Coleta!$G5=Coleta!$G50,1,0))) | L43: =IF(Coleta!$C5<>D$4,"",IF(OR(Coleta!$G5="",Coleta!$G50=""),"",IF(Coleta!$G5=Coleta!$G50,1,0))) -> 1
B44: =IF(Coleta!$C6=B$4,IF(Coleta!$M6="","",Coleta!$M6),"") -> 10 | C44: =IF(Coleta!$C6=C$4,IF(Coleta!$M6="","",Coleta!$M6),"") | D44: =IF(Coleta!$C6=D$4,IF(Coleta!$M6="","",Coleta!$M6),"") | F44: =IF(Coleta!$C6=B$4,IF(Coleta!$N6="","",Coleta!$N6),"") -> 4 | G44: =IF(Coleta!$C6=C$4,IF(Coleta!$N6="","",Coleta!$N6),"") | H44: =IF(Coleta!$C6=D$4,IF(Coleta!$N6="","",Coleta!$N6),"") | J44: =IF(Coleta!$C6<>B$4,"",IF(OR(Coleta!$G6="",Coleta!$G51=""),"",IF(Coleta!$G6=Coleta!$G51,1,0))) -> 1 | K44: =IF(Coleta!$C6<>C$4,"",IF(OR(Coleta!$G6="",Coleta!$G51=""),"",IF(Coleta!$G6=Coleta!$G51,1,0))) | L44: =IF(Coleta!$C6<>D$4,"",IF(OR(Coleta!$G6="",Coleta!$G51=""),"",IF(Coleta!$G6=Coleta!$G51,1,0)))
...
